<script>
    Promise.reject("エラーの理由").catch((err) => {
        console.error(err);
    })
    
    console.log("グローバルコンテキスト終了");
</script>