<script>
    // Promise内でrejectが発生した場合、awaitは例外を発生させるためキャッチ！！！！
    async function throwError() {
        try {
            await Promise.reject("Promiseが失敗しました。");
        } catch (e) {
            console.log(e);
        }
    }

    throwError();
</script>